2025-10-03 00:08:42,705 ERROR: Exception on /login [POST] [in C:\Users\Asus\OneDrive\Desktop\DBMS\.venv\Lib\site-packages\flask\app.py:825]
Traceback (most recent call last):
  File "C:\Users\Asus\OneDrive\Desktop\DBMS\.venv\Lib\site-packages\sqlalchemy\engine\base.py", line 1967, in _exec_single_context
    self.dialect.do_execute(
    ~~~~~~~~~~~~~~~~~~~~~~~^
        cursor, str_statement, effective_parameters, context
        ^^^^^^^^^^^^^^^^^^^^^^^^^^^^^^^^^^^^^^^^^^^^^^^^^^^^
    )
    ^
  File "C:\Users\Asus\OneDrive\Desktop\DBMS\.venv\Lib\site-packages\sqlalchemy\engine\default.py", line 951, in do_execute
    cursor.execute(statement, parameters)
    ~~~~~~~~~~~~~~^^^^^^^^^^^^^^^^^^^^^^^
sqlite3.OperationalError: no such table: User

The above exception was the direct cause of the following exception:

Traceback (most recent call last):
  File "C:\Users\Asus\OneDrive\Desktop\DBMS\.venv\Lib\site-packages\flask\app.py", line 1455, in wsgi_app
    response = self.full_dispatch_request()
  File "C:\Users\Asus\OneDrive\Desktop\DBMS\.venv\Lib\site-packages\flask\app.py", line 869, in full_dispatch_request
    rv = self.handle_user_exception(e)
  File "C:\Users\Asus\OneDrive\Desktop\DBMS\.venv\Lib\site-packages\flask\app.py", line 867, in full_dispatch_request
    rv = self.dispatch_request()
  File "C:\Users\Asus\OneDrive\Desktop\DBMS\.venv\Lib\site-packages\flask\app.py", line 852, in dispatch_request
    return self.ensure_sync(self.view_functions[rule.endpoint])(**view_args)
           ~~~~~~~~~~~~~~~~~~~~~~~~~~~~~~~~~~~~~~~~~~~~~~~~~~~~^^^^^^^^^^^^^
  File "C:\Users\Asus\OneDrive\Desktop\DBMS\.venv\Lib\site-packages\flask_limiter\extension.py", line 1298, in __inner
    return cast(R, flask.current_app.ensure_sync(obj)(*a, **k))
                   ~~~~~~~~~~~~~~~~~~~~~~~~~~~~~~~~~~^^^^^^^^^
  File "C:\Users\Asus\OneDrive\Desktop\DBMS\app\routes.py", line 33, in login
    user = User.query.filter_by(username=form.username.data).first()
  File "C:\Users\Asus\OneDrive\Desktop\DBMS\.venv\Lib\site-packages\sqlalchemy\orm\query.py", line 2759, in first
    return self.limit(1)._iter().first()  # type: ignore
           ~~~~~~~~~~~~~~~~~~~^^
  File "C:\Users\Asus\OneDrive\Desktop\DBMS\.venv\Lib\site-packages\sqlalchemy\orm\query.py", line 2857, in _iter
    result: Union[ScalarResult[_T], Result[_T]] = self.session.execute(
                                                  ~~~~~~~~~~~~~~~~~~~~^
        statement,
        ^^^^^^^^^^
        params,
        ^^^^^^^
        execution_options={"_sa_orm_load_options": self.load_options},
        ^^^^^^^^^^^^^^^^^^^^^^^^^^^^^^^^^^^^^^^^^^^^^^^^^^^^^^^^^^^^^^
    )
    ^
  File "C:\Users\Asus\OneDrive\Desktop\DBMS\.venv\Lib\site-packages\sqlalchemy\orm\session.py", line 2365, in execute
    return self._execute_internal(
           ~~~~~~~~~~~~~~~~~~~~~~^
        statement,
        ^^^^^^^^^^
    ...<4 lines>...
        _add_event=_add_event,
        ^^^^^^^^^^^^^^^^^^^^^^
    )
    ^
  File "C:\Users\Asus\OneDrive\Desktop\DBMS\.venv\Lib\site-packages\sqlalchemy\orm\session.py", line 2251, in _execute_internal
    result: Result[Any] = compile_state_cls.orm_execute_statement(
                          ~~~~~~~~~~~~~~~~~~~~~~~~~~~~~~~~~~~~~~~^
        self,
        ^^^^^
    ...<4 lines>...
        conn,
        ^^^^^
    )
    ^
  File "C:\Users\Asus\OneDrive\Desktop\DBMS\.venv\Lib\site-packages\sqlalchemy\orm\context.py", line 306, in orm_execute_statement
    result = conn.execute(
        statement, params or {}, execution_options=execution_options
    )
  File "C:\Users\Asus\OneDrive\Desktop\DBMS\.venv\Lib\site-packages\sqlalchemy\engine\base.py", line 1419, in execute
    return meth(
        self,
        distilled_parameters,
        execution_options or NO_OPTIONS,
    )
  File "C:\Users\Asus\OneDrive\Desktop\DBMS\.venv\Lib\site-packages\sqlalchemy\sql\elements.py", line 526, in _execute_on_connection
    return connection._execute_clauseelement(
           ~~~~~~~~~~~~~~~~~~~~~~~~~~~~~~~~~^
        self, distilled_params, execution_options
        ^^^^^^^^^^^^^^^^^^^^^^^^^^^^^^^^^^^^^^^^^
    )
    ^
  File "C:\Users\Asus\OneDrive\Desktop\DBMS\.venv\Lib\site-packages\sqlalchemy\engine\base.py", line 1641, in _execute_clauseelement
    ret = self._execute_context(
        dialect,
    ...<8 lines>...
        cache_hit=cache_hit,
    )
  File "C:\Users\Asus\OneDrive\Desktop\DBMS\.venv\Lib\site-packages\sqlalchemy\engine\base.py", line 1846, in _execute_context
    return self._exec_single_context(
           ~~~~~~~~~~~~~~~~~~~~~~~~~^
        dialect, context, statement, parameters
        ^^^^^^^^^^^^^^^^^^^^^^^^^^^^^^^^^^^^^^^
    )
    ^
  File "C:\Users\Asus\OneDrive\Desktop\DBMS\.venv\Lib\site-packages\sqlalchemy\engine\base.py", line 1986, in _exec_single_context
    self._handle_dbapi_exception(
    ~~~~~~~~~~~~~~~~~~~~~~~~~~~~^
        e, str_statement, effective_parameters, cursor, context
        ^^^^^^^^^^^^^^^^^^^^^^^^^^^^^^^^^^^^^^^^^^^^^^^^^^^^^^^
    )
    ^
  File "C:\Users\Asus\OneDrive\Desktop\DBMS\.venv\Lib\site-packages\sqlalchemy\engine\base.py", line 2355, in _handle_dbapi_exception
    raise sqlalchemy_exception.with_traceback(exc_info[2]) from e
  File "C:\Users\Asus\OneDrive\Desktop\DBMS\.venv\Lib\site-packages\sqlalchemy\engine\base.py", line 1967, in _exec_single_context
    self.dialect.do_execute(
    ~~~~~~~~~~~~~~~~~~~~~~~^
        cursor, str_statement, effective_parameters, context
        ^^^^^^^^^^^^^^^^^^^^^^^^^^^^^^^^^^^^^^^^^^^^^^^^^^^^
    )
    ^
  File "C:\Users\Asus\OneDrive\Desktop\DBMS\.venv\Lib\site-packages\sqlalchemy\engine\default.py", line 951, in do_execute
    cursor.execute(statement, parameters)
    ~~~~~~~~~~~~~~^^^^^^^^^^^^^^^^^^^^^^^
sqlalchemy.exc.OperationalError: (sqlite3.OperationalError) no such table: User
[SQL: SELECT "User".id AS "User_id", "User".username AS "User_username", "User".password_hash AS "User_password_hash", "User".role AS "User_role" 
FROM "User" 
WHERE "User".username = ?
 LIMIT ? OFFSET ?]
[parameters: ('admin', 1, 0)]
(Background on this error at: https://sqlalche.me/e/20/e3q8)
2025-10-03 00:08:42,721 ERROR: Server Error: 500 Internal Server Error: The server encountered an internal error and was unable to complete your request. Either the server is overloaded or there is an error in the application. [in C:\Users\Asus\OneDrive\Desktop\DBMS\app\__init__.py:66]
2025-10-03 00:10:51,311 INFO: Disaster Management startup [in C:\Users\Asus\OneDrive\Desktop\DBMS\app\__init__.py:41]
2025-10-03 00:11:55,402 INFO: Disaster Management startup [in C:\Users\Asus\OneDrive\Desktop\DBMS\app\__init__.py:41]
2025-10-03 00:12:16,886 INFO: Disaster Management startup [in C:\Users\Asus\OneDrive\Desktop\DBMS\app\__init__.py:41]
2025-10-03 00:12:23,653 INFO: Disaster Management startup [in C:\Users\Asus\OneDrive\Desktop\DBMS\app\__init__.py:41]
2025-10-03 00:12:37,225 INFO: Disaster Management startup [in C:\Users\Asus\OneDrive\Desktop\DBMS\app\__init__.py:41]
2025-10-03 00:16:15,287 ERROR: Exception on /resource/new [POST] [in C:\Users\Asus\OneDrive\Desktop\DBMS\.venv\Lib\site-packages\flask\app.py:825]
Traceback (most recent call last):
  File "C:\Users\Asus\OneDrive\Desktop\DBMS\.venv\Lib\site-packages\flask\app.py", line 1455, in wsgi_app
    response = self.full_dispatch_request()
  File "C:\Users\Asus\OneDrive\Desktop\DBMS\.venv\Lib\site-packages\flask\app.py", line 869, in full_dispatch_request
    rv = self.handle_user_exception(e)
  File "C:\Users\Asus\OneDrive\Desktop\DBMS\.venv\Lib\site-packages\flask\app.py", line 867, in full_dispatch_request
    rv = self.dispatch_request()
  File "C:\Users\Asus\OneDrive\Desktop\DBMS\.venv\Lib\site-packages\flask\app.py", line 852, in dispatch_request
    return self.ensure_sync(self.view_functions[rule.endpoint])(**view_args)
           ~~~~~~~~~~~~~~~~~~~~~~~~~~~~~~~~~~~~~~~~~~~~~~~~~~~~^^^^^^^^^^^^^
  File "C:\Users\Asus\OneDrive\Desktop\DBMS\.venv\Lib\site-packages\flask_login\utils.py", line 290, in decorated_view
    return current_app.ensure_sync(func)(*args, **kwargs)
           ~~~~~~~~~~~~~~~~~~~~~~~~~~~~~^^^^^^^^^^^^^^^^^
  File "C:\Users\Asus\OneDrive\Desktop\DBMS\app\routes.py", line 17, in decorated_function
    return f(*args, **kwargs)
  File "C:\Users\Asus\OneDrive\Desktop\DBMS\app\routes.py", line 234, in new_resource
    resource = Resource(type=form.type.data, team_id=form.team_id.data if form.team_id.data else None)
  File "<string>", line 4, in __init__
  File "C:\Users\Asus\OneDrive\Desktop\DBMS\.venv\Lib\site-packages\sqlalchemy\orm\state.py", line 571, in _initialize_instance
    with util.safe_reraise():
         ~~~~~~~~~~~~~~~~~^^
  File "C:\Users\Asus\OneDrive\Desktop\DBMS\.venv\Lib\site-packages\sqlalchemy\util\langhelpers.py", line 224, in __exit__
    raise exc_value.with_traceback(exc_tb)
  File "C:\Users\Asus\OneDrive\Desktop\DBMS\.venv\Lib\site-packages\sqlalchemy\orm\state.py", line 569, in _initialize_instance
    manager.original_init(*mixed[1:], **kwargs)
    ~~~~~~~~~~~~~~~~~~~~~^^^^^^^^^^^^^^^^^^^^^^
  File "C:\Users\Asus\OneDrive\Desktop\DBMS\.venv\Lib\site-packages\sqlalchemy\orm\decl_base.py", line 2179, in _declarative_constructor
    raise TypeError(
        "%r is an invalid keyword argument for %s" % (k, cls_.__name__)
    )
TypeError: 'team_id' is an invalid keyword argument for Resource
2025-10-03 00:16:15,327 ERROR: Server Error: 500 Internal Server Error: The server encountered an internal error and was unable to complete your request. Either the server is overloaded or there is an error in the application. [in C:\Users\Asus\OneDrive\Desktop\DBMS\app\__init__.py:66]
