2025-09-25 22:08:12,762 ERROR: Exception on /login [POST] [in C:\Users\Asus\Desktop\DBMS\.venv\Lib\site-packages\flask\app.py:825]
Traceback (most recent call last):
  File "C:\Users\Asus\Desktop\DBMS\.venv\Lib\site-packages\flask\app.py", line 1455, in wsgi_app
    response = self.full_dispatch_request()
  File "C:\Users\Asus\Desktop\DBMS\.venv\Lib\site-packages\flask\app.py", line 869, in full_dispatch_request
    rv = self.handle_user_exception(e)
  File "C:\Users\Asus\Desktop\DBMS\.venv\Lib\site-packages\flask\app.py", line 867, in full_dispatch_request
    rv = self.dispatch_request()
  File "C:\Users\Asus\Desktop\DBMS\.venv\Lib\site-packages\flask\app.py", line 852, in dispatch_request
    return self.ensure_sync(self.view_functions[rule.endpoint])(**view_args)
           ~~~~~~~~~~~~~~~~~~~~~~~~~~~~~~~~~~~~~~~~~~~~~~~~~~~~^^^^^^^^^^^^^
  File "C:\Users\Asus\Desktop\DBMS\.venv\Lib\site-packages\flask_limiter\extension.py", line 1298, in __inner
    return cast(R, flask.current_app.ensure_sync(obj)(*a, **k))
                   ~~~~~~~~~~~~~~~~~~~~~~~~~~~~~~~~~~^^^^^^^^^
  File "C:\Users\Asus\Desktop\DBMS\app\routes.py", line 33, in login
    user = User.query.filter_by(username=form.username.data).first()
  File "C:\Users\Asus\Desktop\DBMS\.venv\Lib\site-packages\sqlalchemy\orm\query.py", line 2759, in first
    return self.limit(1)._iter().first()  # type: ignore
           ~~~~~~~~~~~~~~~~~~~^^
  File "C:\Users\Asus\Desktop\DBMS\.venv\Lib\site-packages\sqlalchemy\orm\query.py", line 2857, in _iter
    result: Union[ScalarResult[_T], Result[_T]] = self.session.execute(
                                                  ~~~~~~~~~~~~~~~~~~~~^
        statement,
        ^^^^^^^^^^
        params,
        ^^^^^^^
        execution_options={"_sa_orm_load_options": self.load_options},
        ^^^^^^^^^^^^^^^^^^^^^^^^^^^^^^^^^^^^^^^^^^^^^^^^^^^^^^^^^^^^^^
    )
    ^
  File "C:\Users\Asus\Desktop\DBMS\.venv\Lib\site-packages\sqlalchemy\orm\session.py", line 2365, in execute
    return self._execute_internal(
           ~~~~~~~~~~~~~~~~~~~~~~^
        statement,
        ^^^^^^^^^^
    ...<4 lines>...
        _add_event=_add_event,
        ^^^^^^^^^^^^^^^^^^^^^^
    )
    ^
  File "C:\Users\Asus\Desktop\DBMS\.venv\Lib\site-packages\sqlalchemy\orm\session.py", line 2241, in _execute_internal
    conn = self._connection_for_bind(bind)
  File "C:\Users\Asus\Desktop\DBMS\.venv\Lib\site-packages\sqlalchemy\orm\session.py", line 2110, in _connection_for_bind
    return trans._connection_for_bind(engine, execution_options)
           ~~~~~~~~~~~~~~~~~~~~~~~~~~^^^^^^^^^^^^^^^^^^^^^^^^^^^
  File "<string>", line 2, in _connection_for_bind
  File "C:\Users\Asus\Desktop\DBMS\.venv\Lib\site-packages\sqlalchemy\orm\state_changes.py", line 137, in _go
    ret_value = fn(self, *arg, **kw)
  File "C:\Users\Asus\Desktop\DBMS\.venv\Lib\site-packages\sqlalchemy\orm\session.py", line 1189, in _connection_for_bind
    conn = bind.connect()
  File "C:\Users\Asus\Desktop\DBMS\.venv\Lib\site-packages\sqlalchemy\engine\base.py", line 3277, in connect
    return self._connection_cls(self)
           ~~~~~~~~~~~~~~~~~~~~^^^^^^
  File "C:\Users\Asus\Desktop\DBMS\.venv\Lib\site-packages\sqlalchemy\engine\base.py", line 143, in __init__
    self._dbapi_connection = engine.raw_connection()
                             ~~~~~~~~~~~~~~~~~~~~~^^
  File "C:\Users\Asus\Desktop\DBMS\.venv\Lib\site-packages\sqlalchemy\engine\base.py", line 3301, in raw_connection
    return self.pool.connect()
           ~~~~~~~~~~~~~~~~~^^
  File "C:\Users\Asus\Desktop\DBMS\.venv\Lib\site-packages\sqlalchemy\pool\base.py", line 447, in connect
    return _ConnectionFairy._checkout(self)
           ~~~~~~~~~~~~~~~~~~~~~~~~~~^^^^^^
  File "C:\Users\Asus\Desktop\DBMS\.venv\Lib\site-packages\sqlalchemy\pool\base.py", line 1264, in _checkout
    fairy = _ConnectionRecord.checkout(pool)
  File "C:\Users\Asus\Desktop\DBMS\.venv\Lib\site-packages\sqlalchemy\pool\base.py", line 711, in checkout
    rec = pool._do_get()
  File "C:\Users\Asus\Desktop\DBMS\.venv\Lib\site-packages\sqlalchemy\pool\impl.py", line 177, in _do_get
    with util.safe_reraise():
         ~~~~~~~~~~~~~~~~~^^
  File "C:\Users\Asus\Desktop\DBMS\.venv\Lib\site-packages\sqlalchemy\util\langhelpers.py", line 224, in __exit__
    raise exc_value.with_traceback(exc_tb)
  File "C:\Users\Asus\Desktop\DBMS\.venv\Lib\site-packages\sqlalchemy\pool\impl.py", line 175, in _do_get
    return self._create_connection()
           ~~~~~~~~~~~~~~~~~~~~~~~^^
  File "C:\Users\Asus\Desktop\DBMS\.venv\Lib\site-packages\sqlalchemy\pool\base.py", line 388, in _create_connection
    return _ConnectionRecord(self)
  File "C:\Users\Asus\Desktop\DBMS\.venv\Lib\site-packages\sqlalchemy\pool\base.py", line 673, in __init__
    self.__connect()
    ~~~~~~~~~~~~~~^^
  File "C:\Users\Asus\Desktop\DBMS\.venv\Lib\site-packages\sqlalchemy\pool\base.py", line 899, in __connect
    with util.safe_reraise():
         ~~~~~~~~~~~~~~~~~^^
  File "C:\Users\Asus\Desktop\DBMS\.venv\Lib\site-packages\sqlalchemy\util\langhelpers.py", line 224, in __exit__
    raise exc_value.with_traceback(exc_tb)
  File "C:\Users\Asus\Desktop\DBMS\.venv\Lib\site-packages\sqlalchemy\pool\base.py", line 895, in __connect
    self.dbapi_connection = connection = pool._invoke_creator(self)
                                         ~~~~~~~~~~~~~~~~~~~~^^^^^^
  File "C:\Users\Asus\Desktop\DBMS\.venv\Lib\site-packages\sqlalchemy\engine\create.py", line 661, in connect
    return dialect.connect(*cargs, **cparams)
           ~~~~~~~~~~~~~~~^^^^^^^^^^^^^^^^^^^
  File "C:\Users\Asus\Desktop\DBMS\.venv\Lib\site-packages\sqlalchemy\engine\default.py", line 629, in connect
    return self.loaded_dbapi.connect(*cargs, **cparams)  # type: ignore[no-any-return]  # NOQA: E501
           ~~~~~~~~~~~~~~~~~~~~~~~~~^^^^^^^^^^^^^^^^^^^
  File "C:\Users\Asus\Desktop\DBMS\.venv\Lib\site-packages\pymysql\connections.py", line 358, in __init__
    self.connect()
    ~~~~~~~~~~~~^^
  File "C:\Users\Asus\Desktop\DBMS\.venv\Lib\site-packages\pymysql\connections.py", line 664, in connect
    self._request_authentication()
    ~~~~~~~~~~~~~~~~~~~~~~~~~~~~^^
  File "C:\Users\Asus\Desktop\DBMS\.venv\Lib\site-packages\pymysql\connections.py", line 976, in _request_authentication
    auth_packet = _auth.caching_sha2_password_auth(self, auth_packet)
  File "C:\Users\Asus\Desktop\DBMS\.venv\Lib\site-packages\pymysql\_auth.py", line 266, in caching_sha2_password_auth
    data = sha2_rsa_encrypt(conn.password, conn.salt, conn.server_public_key)
  File "C:\Users\Asus\Desktop\DBMS\.venv\Lib\site-packages\pymysql\_auth.py", line 143, in sha2_rsa_encrypt
    raise RuntimeError(
    ...<2 lines>...
    )
RuntimeError: 'cryptography' package is required for sha256_password or caching_sha2_password auth methods
2025-09-25 22:08:12,776 ERROR: Server Error: 500 Internal Server Error: The server encountered an internal error and was unable to complete your request. Either the server is overloaded or there is an error in the application. [in C:\Users\Asus\Desktop\DBMS\app\__init__.py:66]
2025-09-25 22:09:04,094 INFO: Disaster Management startup [in C:\Users\Asus\Desktop\DBMS\app\__init__.py:41]
2025-09-25 22:38:28,630 ERROR: Server Error: 500 Internal Server Error: The server encountered an internal error and was unable to complete your request. Either the server is overloaded or there is an error in the application. [in C:\Users\Asus\Desktop\DBMS\app\__init__.py:66]
